I'm sorry, but an uncaught exception occurred.

While running game code:
  File "game/rpycodes/script_1_2.rpy", line 70, in script
    show library day with tran_lf
Exception: Image 'library' does not accept attributes 'day'.

-- Full Traceback ------------------------------------------------------------

Full traceback:
  File "game/rpycodes/script_1_2.rpy", line 70, in script
    show library day with tran_lf
  File "D:\1_file\gal\renpy-8.0.3-sdk\renpy\ast.py", line 1408, in execute
    show_imspec(self.imspec, atl=getattr(self, "atl", None))
  File "D:\1_file\gal\renpy-8.0.3-sdk\renpy\ast.py", line 1371, in show_imspec
    renpy.config.show(name,
  File "D:\1_file\gal\renpy-8.0.3-sdk\renpy\exports.py", line 686, in show
    if not base.find_target() and renpy.config.missing_show:
  File "D:\1_file\gal\renpy-8.0.3-sdk\renpy\display\image.py", line 414, in find_target
    self.target = target._duplicate(a)
  File "D:\1_file\gal\renpy-8.0.3-sdk\renpy\display\core.py", line 397, in _duplicate
    args.extraneous()
  File "D:\1_file\gal\renpy-8.0.3-sdk\renpy\display\core.py", line 265, in extraneous
    raise Exception("Image '{}' does not accept attributes '{}'.".format(
Exception: Image 'library' does not accept attributes 'day'.

Windows-10-10.0.22621 AMD64
Ren'Py 8.0.3.22090809
我们之间的爱恋化作少女来谋杀我 1.0
Sun Nov 27 00:56:30 2022
